Workbook

Sheet National Teams
A1: Rank | B1: Nation | C1: Confederation | D1: Population (m) | E1: Reputation (std) | F1: Var base (population) | G1: Var modifier | H1: Reputation (var) | I1: Range low | J1: Range high | K1: Modifier reason
A2: =RANK(E2,$E$2:$E$212,0) -> 1 | B2: France | C2: UEFA | D2: 68.4 | E2: 85 | F2: =IF(D2<Notes!$B$6,Notes!$C$6,IF(D2<Notes!$B$7,Notes!$C$7,IF(D2<Notes!$B$8,Notes!$C$8,Notes!$C$9))) -> 2 | G2: 0 | H2: =MIN(Notes!$B$3,MAX(1,F2+G2)) -> 2 | I2: =E2-H2 -> 83 | J2: =MIN(E2+H2,Notes!$B$2) -> 85
A3: =RANK(E3,$E$2:$E$212,0) -> 1 | B3: Spain | C3: UEFA | D3: 48.6 | E3: 85 | F3: =IF(D3<Notes!$B$6,Notes!$C$6,IF(D3<Notes!$B$7,Notes!$C$7,IF(D3<Notes!$B$8,Notes!$C$8,Notes!$C$9))) -> 2 | G3: 0 | H3: =MIN(Notes!$B$3,MAX(1,F3+G3)) -> 2 | I3: =E3-H3 -> 83 | J3: =MIN(E3+H3,Notes!$B$2) -> 85
A4: =RANK(E4,$E$2:$E$212,0) -> 3 | B4: Argentina | C4: CONMEBOL | D4: 46 | E4: 84 | F4: =IF(D4<Notes!$B$6,Notes!$C$6,IF(D4<Notes!$B$7,Notes!$C$7,IF(D4<Notes!$B$8,Notes!$C$8,Notes!$C$9))) -> 2 | G4: 0 | H4: =MIN(Notes!$B$3,MAX(1,F4+G4)) -> 2 | I4: =E4-H4 -> 82 | J4: =MIN(E4+H4,Notes!$B$2) -> 85
A5: =RANK(E5,$E$2:$E$212,0) -> 3 | B5: England | C5: UEFA | D5: 57.1 | E5: 84 | F5: =IF(D5<Notes!$B$6,Notes!$C$6,IF(D5<Notes!$B$7,Notes!$C$7,IF(D5<Notes!$B$8,Notes!$C$8,Notes!$C$9))) -> 2 | G5: 0 | H5: =MIN(Notes!$B$3,MAX(1,F5+G5)) -> 2 | I5: =E5-H5 -> 82 | J5: =MIN(E5+H5,Notes!$B$2) -> 85
A6: =RANK(E6,$E$2:$E$212,0) -> 3 | B6: Brazil | C6: CONMEBOL | D6: 213 | E6: 84 | F6: =IF(D6<Notes!$B$6,Notes!$C$6,IF(D6<Notes!$B$7,Notes!$C$7,IF(D6<Notes!$B$8,Notes!$C$8,Notes!$C$9))) -> 2 | G6: 0 | H6: =MIN(Notes!$B$3,MAX(1,F6+G6)) -> 2 | I6: =E6-H6 -> 82 | J6: =MIN(E6+H6,Notes!$B$2) -> 85
A7: =RANK(E7,$E$2:$E$212,0) -> 7 | B7: Portugal | C7: UEFA | D7: 10.6 | E7: 83 | F7: =IF(D7<Notes!$B$6,Notes!$C$6,IF(D7<Notes!$B$7,Notes!$C$7,IF(D7<Notes!$B$8,Notes!$C$8,Notes!$C$9))) -> 4 | G7: 0 | H7: =MIN(Notes!$B$3,MAX(1,F7+G7)) -> 4 | I7: =E7-H7 -> 79 | J7: =MIN(E7+H7,Notes!$B$2) -> 85
A8: =RANK(E8,$E$2:$E$212,0) -> 3 | B8: Germany | C8: UEFA | D8: 83.5 | E8: 84 | F8: =IF(D8<Notes!$B$6,Notes!$C$6,IF(D8<Notes!$B$7,Notes!$C$7,IF(D8<Notes!$B$8,Notes!$C$8,Notes!$C$9))) -> 2 | G8: 0 | H8: =MIN(Notes!$B$3,MAX(1,F8+G8)) -> 2 | I8: =E8-H8 -> 82 | J8: =MIN(E8+H8,Notes!$B$2) -> 85
A9: =RANK(E9,$E$2:$E$212,0) -> 7 | B9: Netherlands | C9: UEFA | D9: 18 | E9: 83 | F9: =IF(D9<Notes!$B$6,Notes!$C$6,IF(D9<Notes!$B$7,Notes!$C$7,IF(D9<Notes!$B$8,Notes!$C$8,Notes!$C$9))) -> 3 | G9: 0 | H9: =MIN(Notes!$B$3,MAX(1,F9+G9)) -> 3 | I9: =E9-H9 -> 80 | J9: =MIN(E9+H9,Notes!$B$2) -> 85
A10: =RANK(E10,$E$2:$E$212,0) -> 10 | B10: Morocco | C10: CAF | D10: 37.8 | E10: 82 | F10: =IF(D10<Notes!$B$6,Notes!$C$6,IF(D10<Notes!$B$7,Notes!$C$7,IF(D10<Notes!$B$8,Notes!$C$8,Notes!$C$9))) -> 3 | G10: 1 | H10: =MIN(Notes!$B$3,MAX(1,F10+G10)) -> 4 | I10: =E10-H10 -> 78 | J10: =MIN(E10+H10,Notes!$B$2) -> 85 | K10: Diaspora-dependent squad
A11: =RANK(E11,$E$2:$E$212,0) -> 11 | B11: Belgium | C11: UEFA | D11: 11.8 | E11: 80 | F11: =IF(D11<Notes!$B$6,Notes!$C$6,IF(D11<Notes!$B$7,Notes!$C$7,IF(D11<Notes!$B$8,Notes!$C$8,Notes!$C$9))) -> 4 | G11: 0 | H11: =MIN(Notes!$B$3,MAX(1,F11+G11)) -> 4 | I11: =E11-H11 -> 76 | J11: =MIN(E11+H11,Notes!$B$2) -> 84
A12: =RANK(E12,$E$2:$E$212,0) -> 7 | B12: Italy | C12: UEFA | D12: 59 | E12: 83 | F12: =IF(D12<Notes!$B$6,Notes!$C$6,IF(D12<Notes!$B$7,Notes!$C$7,IF(D12<Notes!$B$8,Notes!$C$8,Notes!$C$9))) -> 2 | G12: 0 | H12: =MIN(Notes!$B$3,MAX(1,F12+G12)) -> 2 | I12: =E12-H12 -> 81 | J12: =MIN(E12+H12,Notes!$B$2) -> 85
A13: =RANK(E13,$E$2:$E$212,0) -> 11 | B13: Colombia | C13: CONMEBOL | D13: 53 | E13: 80 | F13: =IF(D13<Notes!$B$6,Notes!$C$6,IF(D13<Notes!$B$7,Notes!$C$7,IF(D13<Notes!$B$8,Notes!$C$8,Notes!$C$9))) -> 2 | G13: 0 | H13: =MIN(Notes!$B$3,MAX(1,F13+G13)) -> 2 | I13: =E13-H13 -> 78 | J13: =MIN(E13+H13,Notes!$B$2) -> 82
A14: =RANK(E14,$E$2:$E$212,0) -> 11 | B14: Uruguay | C14: CONMEBOL | D14: 3.4 | E14: 80 | F14: =IF(D14<Notes!$B$6,Notes!$C$6,IF(D14<Notes!$B$7,Notes!$C$7,IF(D14<Notes!$B$8,Notes!$C$8,Notes!$C$9))) -> 5 | G14: 0 | H14: =MIN(Notes!$B$3,MAX(1,F14+G14)) -> 5 | I14: =E14-H14 -> 75 | J14: =MIN(E14+H14,Notes!$B$2) -> 85
A15: =RANK(E15,$E$2:$E$212,0) -> 17 | B15: Croatia | C15: UEFA | D15: 3.86 | E15: 78 | F15: =IF(D15<Notes!$B$6,Notes!$C$6,IF(D15<Notes!$B$7,Notes!$C$7,IF(D15<Notes!$B$8,Notes!$C$8,Notes!$C$9))) -> 5 | G15: 0 | H15: =MIN(Notes!$B$3,MAX(1,F15+G15)) -> 5 | I15: =E15-H15 -> 73 | J15: =MIN(E15+H15,Notes!$B$2) -> 83
A16: =RANK(E16,$E$2:$E$212,0) -> 14 | B16: Japan | C16: AFC | D16: 123.5 | E16: 79 | F16: =IF(D16<Notes!$B$6,Notes!$C$6,IF(D16<Notes!$B$7,Notes!$C$7,IF(D16<Notes!$B$8,Notes!$C$8,Notes!$C$9))) -> 2 | G16: 0 | H16: =MIN(Notes!$B$3,MAX(1,F16+G16)) -> 2 | I16: =E16-H16 -> 77 | J16: =MIN(E16+H16,Notes!$B$2) -> 81
A17: =RANK(E17,$E$2:$E$212,0) -> 17 | B17: Senegal | C17: CAF | D17: 18.5 | E17: 78 | F17: =IF(D17<Notes!$B$6,Notes!$C$6,IF(D17<Notes!$B$7,Notes!$C$7,IF(D17<Notes!$B$8,Notes!$C$8,Notes!$C$9))) -> 3 | G17: 1 | H17: =MIN(Notes!$B$3,MAX(1,F17+G17)) -> 4 | I17: =E17-H17 -> 74 | J17: =MIN(E17+H17,Notes!$B$2) -> 82 | K17: Diaspora-dependent squad
A18: =RANK(E18,$E$2:$E$212,0) -> 19 | B18: Mexico | C18: CONCACAF | D18: 131 | E18: 77 | F18: =IF(D18<Notes!$B$6,Notes!$C$6,IF(D18<Notes!$B$7,Notes!$C$7,IF(D18<Notes!$B$8,Notes!$C$8,Notes!$C$9))) -> 2 | G18: 0 | H18: =MIN(Notes!$B$3,MAX(1,F18+G18)) -> 2 | I18: =E18-H18 -> 75 | J18: =MIN(E18+H18,Notes!$B$2) -> 79
A19: =RANK(E19,$E$2:$E$212,0) -> 14 | B19: Norway | C19: UEFA | D19: 5.6 | E19: 79 | F19: =IF(D19<Notes!$B$6,Notes!$C$6,IF(D19<Notes!$B$7,Notes!$C$7,IF(D19<Notes!$B$8,Notes!$C$8,Notes!$C$9))) -> 4 | G19: 0 | H19: =MIN(Notes!$B$3,MAX(1,F19+G19)) -> 4 | I19: =E19-H19 -> 75 | J19: =MIN(E19+H19,Notes!$B$2) -> 83
A20: =RANK(E20,$E$2:$E$212,0) -> 14 | B20: Switzerland | C20: UEFA | D20: 9 | E20: 79 | F20: =IF(D20<Notes!$B$6,Notes!$C$6,IF(D20<Notes!$B$7,Notes!$C$7,IF(D20<Notes!$B$8,Notes!$C$8,Notes!$C$9))) -> 4 | G20: 0 | H20: =MIN(Notes!$B$3,MAX(1,F20+G20)) -> 4 | I20: =E20-H20 -> 75 | J20: =MIN(E20+H20,Notes!$B$2) -> 83
A21: =RANK(E21,$E$2:$E$212,0) -> 19 | B21: United States | C21: CONCACAF | D21: 340 | E21: 77 | F21: =IF(D21<Notes!$B$6,Notes!$C$6,IF(D21<Notes!$B$7,Notes!$C$7,IF(D21<Notes!$B$8,Notes!$C$8,Notes!$C$9))) -> 2 | G21: 1 | H21: =MIN(Notes!$B$3,MAX(1,F21+G21)) -> 3 | I21: =E21-H21 -> 74 | J21: =MIN(E21+H21,Notes!$B$2) -> 80 | K21: Emerging / investment-driven programme
A22: =RANK(E22,$E$2:$E$212,0) -> 19 | B22: Ecuador | C22: CONMEBOL | D22: 18 | E22: 77 | F22: =IF(D22<Notes!$B$6,Notes!$C$6,IF(D22<Notes!$B$7,Notes!$C$7,IF(D22<Notes!$B$8,Notes!$C$8,Notes!$C$9))) -> 3 | G22: 0 | H22: =MIN(Notes!$B$3,MAX(1,F22+G22)) -> 3 | I22: =E22-H22 -> 74 | J22: =MIN(E22+H22,Notes!$B$2) -> 80
A23: =RANK(E23,$E$2:$E$212,0) -> 19 | B23: Denmark | C23: UEFA | D23: 6 | E23: 77 | F23: =IF(D23<Notes!$B$6,Notes!$C$6,IF(D23<Notes!$B$7,Notes!$C$7,IF(D23<Notes!$B$8,Notes!$C$8,Notes!$C$9))) -> 4 | G23: 0 | H23: =MIN(Notes!$B$3,MAX(1,F23+G23)) -> 4 | I23: =E23-H23 -> 73 | J23: =MIN(E23+H23,Notes!$B$2) -> 81
A24: =RANK(E24,$E$2:$E$212,0) -> 19 | B24: Türkiye | C24: UEFA | D24: 85.7 | E24: 77 | F24: =IF(D24<Notes!$B$6,Notes!$C$6,IF(D24<Notes!$B$7,Notes!$C$7,IF(D24<Notes!$B$8,Notes!$C$8,Notes!$C$9))) -> 2 | G24: 1 | H24: =MIN(Notes!$B$3,MAX(1,F24+G24)) -> 3 | I24: =E24-H24 -> 74 | J24: =MIN(E24+H24,Notes!$B$2) -> 80 | K24: Diaspora-dependent squad
A25: =RANK(E25,$E$2:$E$212,0) -> 25 | B25: Ivory Coast | C25: CAF | D25: 31.9 | E25: 76 | F25: =IF(D25<Notes!$B$6,Notes!$C$6,IF(D25<Notes!$B$7,Notes!$C$7,IF(D25<Notes!$B$8,Notes!$C$8,Notes!$C$9))) -> 3 | G25: 1 | H25: =MIN(Notes!$B$3,MAX(1,F25+G25)) -> 4 | I25: =E25-H25 -> 72 | J25: =MIN(E25+H25,Notes!$B$2) -> 80 | K25: Diaspora-dependent squad
A26: =RANK(E26,$E$2:$E$212,0) -> 25 | B26: Nigeria | C26: CAF | D26: 230 | E26: 76 | F26: =IF(D26<Notes!$B$6,Notes!$C$6,IF(D26<Notes!$B$7,Notes!$C$7,IF(D26<Notes!$B$8,Notes!$C$8,Notes!$C$9))) -> 2 | G26: 0 | H26: =MIN(Notes!$B$3,MAX(1,F26+G26)) -> 2 | I26: =E26-H26 -> 74 | J26: =MIN(E26+H26,Notes!$B$2) -> 78
A27: =RANK(E27,$E$2:$E$212,0) -> 25 | B27: Austria | C27: UEFA | D27: 9.2 | E27: 76 | F27: =IF(D27<Notes!$B$6,Notes!$C$6,IF(D27<Notes!$B$7,Notes!$C$7,IF(D27<Notes!$B$8,Notes!$C$8,Notes!$C$9))) -> 4 | G27: 0 | H27: =MIN(Notes!$B$3,MAX(1,F27+G27)) -> 4 | I27: =E27-H27 -> 72 | J27: =MIN(E27+H27,Notes!$B$2) -> 80
A28: =RANK(E28,$E$2:$E$212,0) -> 19 | B28: South Korea | C28: AFC | D28: 51.7 | E28: 77 | F28: =IF(D28<Notes!$B$6,Notes!$C$6,IF(D28<Notes!$B$7,Notes!$C$7,IF(D28<Notes!$B$8,Notes!$C$8,Notes!$C$9))) -> 2 | G28: 0 | H28: =MIN(Notes!$B$3,MAX(1,F28+G28)) -> 2 | I28: =E28-H28 -> 75 | J28: =MIN(E28+H28,Notes!$B$2) -> 79
A29: =RANK(E29,$E$2:$E$212,0) -> 28 | B29: Algeria | C29: CAF | D29: 47 | E29: 75 | F29: =IF(D29<Notes!$B$6,Notes!$C$6,IF(D29<Notes!$B$7,Notes!$C$7,IF(D29<Notes!$B$8,Notes!$C$8,Notes!$C$9))) -> 2 | G29: 1 | H29: =MIN(Notes!$B$3,MAX(1,F29+G29)) -> 3 | I29: =E29-H29 -> 72 | J29: =MIN(E29+H29,Notes!$B$2) -> 78 | K29: Diaspora-dependent squad
A30: =RANK(E30,$E$2:$E$212,0) -> 28 | B30: Egypt | C30: CAF | D30: 116 | E30: 75 | F30: =IF(D30<Notes!$B$6,Notes!$C$6,IF(D30<Notes!$B$7,Notes!$C$7,IF(D30<Notes!$B$8,Notes!$C$8,Notes!$C$9))) -> 2 | G30: 0 | H30: =MIN(Notes!$B$3,MAX(1,F30+G30)) -> 2 | I30: =E30-H30 -> 73 | J30: =MIN(E30+H30,Notes!$B$2) -> 77
A31: =RANK(E31,$E$2:$E$212,0) -> 28 | B31: Canada | C31: CONCACAF | D31: 41.5 | E31: 75 | F31: =IF(D31<Notes!$B$6,Notes!$C$6,IF(D31<Notes!$B$7,Notes!$C$7,IF(D31<Notes!$B$8,Notes!$C$8,Notes!$C$9))) -> 2 | G31: 1 | H31: =MIN(Notes!$B$3,MAX(1,F31+G31)) -> 3 | I31: =E31-H31 -> 72 | J31: =MIN(E31+H31,Notes!$B$2) -> 78 | K31: Emerging / investment-driven programme
A32: =RANK(E32,$E$2:$E$212,0) -> 33 | B32: Paraguay | C32: CONMEBOL | D32: 6.9 | E32: 74 | F32: =IF(D32<Notes!$B$6,Notes!$C$6,IF(D32<Notes!$B$7,Notes!$C$7,IF(D32<Notes!$B$8,Notes!$C$8,Notes!$C$9))) -> 4 | G32: 0 | H32: =MIN(Notes!$B$3,MAX(1,F32+G32)) -> 4 | I32: =E32-H32 -> 70 | J32: =MIN(E32+H32,Notes!$B$2) -> 78
A33: =RANK(E33,$E$2:$E$212,0) -> 28 | B33: Sweden | C33: UEFA | D33: 10.6 | E33: 75 | F33: =IF(D33<Notes!$B$6,Notes!$C$6,IF(D33<Notes!$B$7,Notes!$C$7,IF(D33<Notes!$B$8,Notes!$C$8,Notes!$C$9))) -> 4 | G33: 0 | H33: =MIN(Notes!$B$3,MAX(1,F33+G33)) -> 4 | I33: =E33-H33 -> 71 | J33: =MIN(E33+H33,Notes!$B$2) -> 79
A34: =RANK(E34,$E$2:$E$212,0) -> 28 | B34: Ukraine | C34: UEFA | D34: 33 | E34: 75 | F34: =IF(D34<Notes!$B$6,Notes!$C$6,IF(D34<Notes!$B$7,Notes!$C$7,IF(D34<Notes!$B$8,Notes!$C$8,Notes!$C$9))) -> 3 | G34: 0 | H34: =MIN(Notes!$B$3,MAX(1,F34+G34)) -> 3 | I34: =E34-H34 -> 72 | J34: =MIN(E34+H34,Notes!$B$2) -> 78
A35: =RANK(E35,$E$2:$E$212,0) -> 33 | B35: Iran | C35: AFC | D35: 91 | E35: 74 | F35: =IF(D35<Notes!$B$6,Notes!$C$6,IF(D35<Notes!$B$7,Notes!$C$7,IF(D35<Notes!$B$8,Notes!$C$8,Notes!$C$9))) -> 2 | G35: 0 | H35: =MIN(Notes!$B$3,MAX(1,F35+G35)) -> 2 | I35: =E35-H35 -> 72 | J35: =MIN(E35+H35,Notes!$B$2) -> 76
A36: =RANK(E36,$E$2:$E$212,0) -> 33 | B36: Poland | C36: UEFA | D36: 36.6 | E36: 74 | F36: =IF(D36<Notes!$B$6,Notes!$C$6,IF(D36<Notes!$B$7,Notes!$C$7,IF(D36<Notes!$B$8,Notes!$C$8,Notes!$C$9))) -> 3 | G36: 0 | H36: =MIN(Notes!$B$3,MAX(1,F36+G36)) -> 3 | I36: =E36-H36 -> 71 | J36: =MIN(E36+H36,Notes!$B$2) -> 77
A37: =RANK(E37,$E$2:$E$212,0) -> 33 | B37: Serbia | C37: UEFA | D37: 6.6 | E37: 74 | F37: =IF(D37<Notes!$B$6,Notes!$C$6,IF(D37<Notes!$B$7,Notes!$C$7,IF(D37<Notes!$B$8,Notes!$C$8,Notes!$C$9))) -> 4 | G37: 0 | H37: =MIN(Notes!$B$3,MAX(1,F37+G37)) -> 4 | I37: =E37-H37 -> 70 | J37: =MIN(E37+H37,Notes!$B$2) -> 78
A38: =RANK(E38,$E$2:$E$212,0) -> 45 | B38: Australia | C38: AFC | D38: 27.2 | E38: 72 | F38: =IF(D38<Notes!$B$6,Notes!$C$6,IF(D38<Notes!$B$7,Notes!$C$7,IF(D38<Notes!$B$8,Notes!$C$8,Notes!$C$9))) -> 3 | G38: 0 | H38: =MIN(Notes!$B$3,MAX(1,F38+G38)) -> 3 | I38: =E38-H38 -> 69 | J38: =MIN(E38+H38,Notes!$B$2) -> 75
A39: =RANK(E39,$E$2:$E$212,0) -> 37 | B39: Cameroon | C39: CAF | D39: 29 | E39: 73 | F39: =IF(D39<Notes!$B$6,Notes!$C$6,IF(D39<Notes!$B$7,Notes!$C$7,IF(D39<Notes!$B$8,Notes!$C$8,Notes!$C$9))) -> 3 | G39: 0 | H39: =MIN(Notes!$B$3,MAX(1,F39+G39)) -> 3 | I39: =E39-H39 -> 70 | J39: =MIN(E39+H39,Notes!$B$2) -> 76
A40: =RANK(E40,$E$2:$E$212,0) -> 37 | B40: DR Congo | C40: CAF | D40: 112 | E40: 73 | F40: =IF(D40<Notes!$B$6,Notes!$C$6,IF(D40<Notes!$B$7,Notes!$C$7,IF(D40<Notes!$B$8,Notes!$C$8,Notes!$C$9))) -> 2 | G40: 1 | H40: =MIN(Notes!$B$3,MAX(1,F40+G40)) -> 3 | I40: =E40-H40 -> 70 | J40: =MIN(E40+H40,Notes!$B$2) -> 76 | K40: Diaspora-dependent squad
...

Sheet By Confederation
A1: Confederation | B1: Members | C1: Best (std) | D1: Average (std) | E1: Weakest (std) | F1: Average var
A2: UEFA | B2: =COUNTIF('National Teams'!$C$2:$C$212,A2) -> 55 | C2: =_xlfn.MAXIFS('National Teams'!$E$2:$E$212,'National Teams'!$C$2:$C$212,A2) -> 85 | D2: =AVERAGEIF('National Teams'!$C$2:$C$212,A2,'National Teams'!$E$2:$E$212) -> 66.545455 | E2: =_xlfn.MINIFS('National Teams'!$E$2:$E$212,'National Teams'!$C$2:$C$212,A2) -> 31 | F2: =AVERAGEIF('National Teams'!$C$2:$C$212,A2,'National Teams'!$H$2:$H$212) -> 4.1090909
A3: CONMEBOL | B3: =COUNTIF('National Teams'!$C$2:$C$212,A3) -> 10 | C3: =_xlfn.MAXIFS('National Teams'!$E$2:$E$212,'National Teams'!$C$2:$C$212,A3) -> 84 | D3: =AVERAGEIF('National Teams'!$C$2:$C$212,A3,'National Teams'!$E$2:$E$212) -> 75.1 | E3: =_xlfn.MINIFS('National Teams'!$E$2:$E$212,'National Teams'!$C$2:$C$212,A3) -> 62 | F3: =AVERAGEIF('National Teams'!$C$2:$C$212,A3,'National Teams'!$H$2:$H$212) -> 3.1
A4: CONCACAF | B4: =COUNTIF('National Teams'!$C$2:$C$212,A4) -> 35 | C4: =_xlfn.MAXIFS('National Teams'!$E$2:$E$212,'National Teams'!$C$2:$C$212,A4) -> 77 | D4: =AVERAGEIF('National Teams'!$C$2:$C$212,A4,'National Teams'!$E$2:$E$212) -> 46.085714 | E4: =_xlfn.MINIFS('National Teams'!$E$2:$E$212,'National Teams'!$C$2:$C$212,A4) -> 25 | F4: =AVERAGEIF('National Teams'!$C$2:$C$212,A4,'National Teams'!$H$2:$H$212) -> 4.5428571
A5: CAF | B5: =COUNTIF('National Teams'!$C$2:$C$212,A5) -> 54 | C5: =_xlfn.MAXIFS('National Teams'!$E$2:$E$212,'National Teams'!$C$2:$C$212,A5) -> 82 | D5: =AVERAGEIF('National Teams'!$C$2:$C$212,A5,'National Teams'!$E$2:$E$212) -> 57.518519 | E5: =_xlfn.MINIFS('National Teams'!$E$2:$E$212,'National Teams'!$C$2:$C$212,A5) -> 30 | F5: =AVERAGEIF('National Teams'!$C$2:$C$212,A5,'National Teams'!$H$2:$H$212) -> 3.7037037
A6: AFC | B6: =COUNTIF('National Teams'!$C$2:$C$212,A6) -> 46 | C6: =_xlfn.MAXIFS('National Teams'!$E$2:$E$212,'National Teams'!$C$2:$C$212,A6) -> 79 | D6: =AVERAGEIF('National Teams'!$C$2:$C$212,A6,'National Teams'!$E$2:$E$212) -> 48.413043 | E6: =_xlfn.MINIFS('National Teams'!$E$2:$E$212,'National Teams'!$C$2:$C$212,A6) -> 25 | F6: =AVERAGEIF('National Teams'!$C$2:$C$212,A6,'National Teams'!$H$2:$H$212) -> 3.4565217
A7: OFC | B7: =COUNTIF('National Teams'!$C$2:$C$212,A7) -> 11 | C7: =_xlfn.MAXIFS('National Teams'!$E$2:$E$212,'National Teams'!$C$2:$C$212,A7) -> 65 | D7: =AVERAGEIF('National Teams'!$C$2:$C$212,A7,'National Teams'!$E$2:$E$212) -> 30.363636 | E7: =_xlfn.MINIFS('National Teams'!$E$2:$E$212,'National Teams'!$C$2:$C$212,A7) -> 25 | F7: =AVERAGEIF('National Teams'!$C$2:$C$212,A7,'National Teams'!$H$2:$H$212) -> 4.8181818
A8: Total | B8: =SUM(B2:B7) -> 211 | C8: =MAX('National Teams'!$E$2:$E$212) -> 85 | D8: =AVERAGE('National Teams'!$E$2:$E$212) -> 55.407583 | E8: =MIN('National Teams'!$E$2:$E$212) -> 25 | F8: =AVERAGE('National Teams'!$H$2:$H$212) -> 3.9241706

Sheet Notes
A1: Settings
A2: Reputation cap (best national team) | B2: 85 | D2: User spec: best clubs 90, best national teams 85. Range high never exceeds this.
A3: Max sway (var) | B3: 5 | D3: User spec: sway is never more than 5.
A5: Population band | B5: Upper limit (m) | C5: Base var
A6: Under 5 million | B6: 5 | C6: 5 | D6: Smaller talent pools swing harder: one golden generation (Croatia, Uruguay, Iceland) moves the whole team.
A7: 5 to 15 million | B7: 15 | C7: 4
A8: 15 to 40 million | B8: 40 | C8: 3
A9: 40 million and above | B9: — | C9: 2 | D9: Large pools average out: Germany or Brazil always has depth, so they move least.
A12: Columns
A13: Reputation (std) | D13: Baseline level at game start (2026). Anchored on the FIFA men's ranking of 20 July 2026 (after the 2026 World Cup), adjusted for squad talent. Edit freely (blue).
A14: Var base | D14: Formula: set by population band above.
A15: Var modifier | D15: Manual +1 for nations whose talent supply is unusually volatile: diaspora-dependent squads, naturalisation, or investment-driven programmes. Reason in column K. Edit freely (blue).
A16: Reputation (var) | D16: Formula: base + modifier, clamped between 1 and the max sway (5). The maximum a nation can move away from its std, up or down, over a ~20-year period.
A17: Range low / high | D17: Formula: std − var and std + var, with high capped at the reputation cap.
A19: Scope | D19: All 211 FIFA member associations. Russia is included as a FIFA member but is currently suspended from UEFA and FIFA competitions. The four UK nations are listed separately with their own populations.
A20: Populations | D20: Approximate 2025 figures in millions, rounded. Only the band matters for the formula, so small inaccuracies don't change the result.
A22: Suggested engine use | D22: Each nation's current rep drifts inside [low, high] around its std, e.g. a slow wave over ~20 years with a random phase per nation, plus small yearly noise. Golden generations are the crests of that wave; nations with a high var have bigger crests and troughs.
